<?xml version="1.0" encoding="UTF-8"?>
<!-- Generated by org.testng.reporters.JUnitReportReporter -->
<testsuite hostname="LAPTOP-CVVOB1KD" failures="1" tests="1" name="com.APIFramework.APITestCases.HTTPMethod_DELETE" time="1.058" errors="0" timestamp="2020-05-17T01:02:30 IST" skipped="0">
  <testcase classname="com.APIFramework.APITestCases.HTTPMethod_DELETE" name="deleteEmployeeData" time="1.058">
    <failure message="expected [success] but found [failed]" type="java.lang.AssertionError">
      <![CDATA[java.lang.AssertionError: expected [success] but found [failed]
at org.testng.Assert.fail(Assert.java:97)
at org.testng.Assert.assertEqualsImpl(Assert.java:136)
at org.testng.Assert.assertEquals(Assert.java:118)
at org.testng.Assert.assertEquals(Assert.java:575)
at org.testng.Assert.assertEquals(Assert.java:585)
at com.APIFramework.APITestCases.HTTPMethod_DELETE.deleteEmployeeData(HTTPMethod_DELETE.java:37)
at java.base/jdk.internal.reflect.NativeMethodAccessorImpl.invoke0(Native Method)
at java.base/jdk.internal.reflect.NativeMethodAccessorImpl.invoke(NativeMethodAccessorImpl.java:62)
at java.base/jdk.internal.reflect.DelegatingMethodAccessorImpl.invoke(DelegatingMethodAccessorImpl.java:43)
at java.base/java.lang.reflect.Method.invoke(Method.java:567)
at org.testng.internal.MethodInvocationHelper.invokeMethod(MethodInvocationHelper.java:135)
at org.testng.internal.TestInvoker.invokeMethod(TestInvoker.java:598)
at org.testng.internal.TestInvoker.invokeTestMethod(TestInvoker.java:174)
at org.testng.internal.MethodRunner.runInSequence(MethodRunner.java:46)
at org.testng.internal.TestInvoker$MethodInvocationAgent.invoke(TestInvoker.java:821)
at org.testng.internal.TestInvoker.invokeTestMethods(TestInvoker.java:147)
at org.testng.internal.TestMethodWorker.invokeTestMethods(TestMethodWorker.java:146)
at org.testng.internal.TestMethodWorker.run(TestMethodWorker.java:128)
at java.base/java.util.ArrayList.forEach(ArrayList.java:1540)
at org.testng.TestRunner.privateRun(TestRunner.java:767)
at org.testng.TestRunner.run(TestRunner.java:588)
at org.testng.SuiteRunner.runTest(SuiteRunner.java:384)
at org.testng.SuiteRunner.runSequentially(SuiteRunner.java:378)
at org.testng.SuiteRunner.privateRun(SuiteRunner.java:337)
at org.testng.SuiteRunner.run(SuiteRunner.java:286)
at org.testng.SuiteRunnerWorker.runSuite(SuiteRunnerWorker.java:53)
at org.testng.SuiteRunnerWorker.run(SuiteRunnerWorker.java:96)
at org.testng.TestNG.runSuitesSequentially(TestNG.java:1214)
at org.testng.TestNG.runSuitesLocally(TestNG.java:1136)
at org.testng.TestNG.runSuites(TestNG.java:1066)
at org.testng.TestNG.run(TestNG.java:1034)
at org.testng.remote.AbstractRemoteTestNG.run(AbstractRemoteTestNG.java:115)
at org.testng.remote.RemoteTestNG.initAndRun(RemoteTestNG.java:251)
at org.testng.remote.RemoteTestNG.main(RemoteTestNG.java:77)
]]>
    </failure>
  </testcase> <!-- deleteEmployeeData -->
  <system-out>
Request log :: http://dummy.restapiexample.com/api/v1/delete/87 Response log :: {"status":"failed","message":"Error! Not able to delete record"}  </system-out>
</testsuite> <!-- com.APIFramework.APITestCases.HTTPMethod_DELETE -->
